Exception in thread Thread-1:
Traceback (most recent call last):
  File "/usr/lib/python3/dist-packages/urllib3/connection.py", line 137, in _new_conn
    (self.host, self.port), self.timeout, **extra_kw)
  File "/usr/lib/python3/dist-packages/urllib3/util/connection.py", line 91, in create_connection
    raise err
  File "/usr/lib/python3/dist-packages/urllib3/util/connection.py", line 81, in create_connection
    sock.connect(sa)
BlockingIOError: [Errno 11] Resource temporarily unavailable

During handling of the above exception, another exception occurred:

Traceback (most recent call last):
  File "/usr/lib/python3/dist-packages/urllib3/connectionpool.py", line 560, in urlopen
    body=body, headers=headers)
  File "/usr/lib/python3/dist-packages/urllib3/connectionpool.py", line 346, in _make_request
    self._validate_conn(conn)
  File "/usr/lib/python3/dist-packages/urllib3/connectionpool.py", line 787, in _validate_conn
    conn.connect()
  File "/usr/lib/python3/dist-packages/urllib3/connection.py", line 217, in connect
    conn = self._new_conn()
  File "/usr/lib/python3/dist-packages/urllib3/connection.py", line 146, in _new_conn
    self, "Failed to establish a new connection: %s" % e)
requests.packages.urllib3.exceptions.NewConnectionError: <requests.packages.urllib3.connection.VerifiedHTTPSConnection object at 0x7f0a17c9d5c0>: Failed to
 establish a new connection: [Errno 11] Resource temporarily unavailable

During handling of the above exception, another exception occurred:

Traceback (most recent call last):
  File "/usr/lib/python3/dist-packages/requests/adapters.py", line 376, in send
    timeout=timeout
  File "/usr/lib/python3/dist-packages/urllib3/connectionpool.py", line 610, in urlopen
    _stacktrace=sys.exc_info()[2])
  File "/usr/lib/python3/dist-packages/urllib3/util/retry.py", line 273, in increment
    raise MaxRetryError(_pool, url, error or ResponseError(cause))
requests.packages.urllib3.exceptions.MaxRetryError: HTTPSConnectionPool(host='gateway.watsonplatform.net', port=443): Max retries exceeded with url: /tone-
analyzer/api/v3/tone?version=2016-05-19 (Caused by NewConnectionError('<requests.packages.urllib3.connection.VerifiedHTTPSConnection object at 0x7f0a17c9d5
c0>: Failed to establish a new connection: [Errno 11] Resource temporarily unavailable',))

During handling of the above exception, another exception occurred:

Traceback (most recent call last):
  File "/usr/lib/python3.5/threading.py", line 914, in _bootstrap_inner
    self.run()
  File "/usr/lib/python3.5/threading.py", line 862, in run
    self._target(*self._args, **self._kwargs)
  File "/mnt/c/Users/jdhus/Documents/Fall_2017/IrishHacks/att-hack-2017/ToxBot.py", line 55, in analyze_tone
    score = analyzer.get_score(message[1])
  File "/mnt/c/Users/jdhus/Documents/Fall_2017/IrishHacks/att-hack-2017/ToneAnalyzer.py", line 56, in get_score
    data = self.tone_analyzer.tone(text=message)
  File "/usr/local/lib/python3.5/dist-packages/watson_developer_cloud/tone_analyzer_v3.py", line 75, in tone
    json=text, accept_json=True)
  File "/usr/local/lib/python3.5/dist-packages/watson_developer_cloud/watson_developer_cloud_service.py", line 302, in request
    **kwargs)
  File "/usr/lib/python3/dist-packages/requests/api.py", line 53, in request
    return session.request(method=method, url=url, **kwargs)
  File "/usr/lib/python3/dist-packages/requests/sessions.py", line 468, in request
    resp = self.send(prep, **send_kwargs)
  File "/usr/lib/python3/dist-packages/requests/sessions.py", line 576, in send
    r = adapter.send(request, **kwargs)
  File "/usr/lib/python3/dist-packages/requests/adapters.py", line 437, in send
    raise ConnectionError(e, request=request)
requests.exceptions.ConnectionError: HTTPSConnectionPool(host='gateway.watsonplatform.net', port=443): Max retries exceeded with url: /tone-analyzer/api/v3
/tone?version=2016-05-19 (Caused by NewConnectionError('<requests.packages.urllib3.connection.VerifiedHTTPSConnection object at 0x7f0a17c9d5c0>: Failed to
establish a new connection: [Errno 11] Resource temporarily unavailable',)